Testing started at 20:29 ...
C:\Users\malee\PycharmProjects\DirectLineTest\venv\Scripts\python.exe "C:\Program Files\JetBrains\PyCharm 2018.3.4\helpers\pycharm\_jb_unittest_runner.py" --path C:/Users/malee/PycharmProjects/DirectLineTest/tests/test_duplicates.py
Console output is saving to: C:\SparkDemoFiles
Launching unittests with arguments python -m unittest C:/Users/malee/PycharmProjects/DirectLineTest/tests/test_duplicates.py in C:\Users\malee\PycharmProjects\DirectLineTest\tests
20/05/03 20:29:40 WARN NativeCodeLoader: Unable to load native-hadoop library for your platform... using builtin-java classes where applicable
Using Spark's default log4j profile: org/apache/spark/log4j-defaults.properties
Setting default log level to "WARN".
To adjust logging level use sc.setLogLevel(newLevel). For SparkR, use setLogLevel(newLevel).
20/05/03 20:29:41 WARN Utils: Service 'SparkUI' could not bind on port 4040. Attempting port 4041.
20/05/03 20:29:41 WARN Utils: Service 'SparkUI' could not bind on port 4041. Attempting port 4042.
20/05/03 20:29:41 WARN Utils: Service 'SparkUI' could not bind on port 4042. Attempting port 4043.
20/05/03 20:29:57 WARN TaskSetManager: Stage 0 contains a task of very large size (8053 KB). The maximum recommended task size is 100 KB.
C:\Users\malee\Anaconda3\lib\socket.py:657: ResourceWarning: unclosed <socket.socket fd=1696, family=AddressFamily.AF_INET, type=SocketKind.SOCK_STREAM, proto=0, laddr=('127.0.0.1', 61289), raddr=('127.0.0.1', 61288)>
  self._sock = None

Failure
Traceback (most recent call last):
  File "C:\Users\malee\Anaconda3\lib\unittest\case.py", line 59, in testPartExecutor
    yield
  File "C:\Users\malee\Anaconda3\lib\unittest\case.py", line 605, in run
    testMethod()
  File "C:\Users\malee\PycharmProjects\DirectLineTest\tests\test_duplicates.py", line 74, in test_data_frame
    assert_frame_equal(results_pandas, expected_results)
  File "C:\Users\malee\PycharmProjects\DirectLineTest\venv\lib\site-packages\pandas\_testing.py", line 1325, in assert_frame_equal
    obj, f"{obj} shape mismatch", f"{repr(left.shape)}", f"{repr(right.shape)}",
  File "C:\Users\malee\PycharmProjects\DirectLineTest\venv\lib\site-packages\pandas\_testing.py", line 915, in raise_assert_detail
    raise AssertionError(msg)
AssertionError: DataFrame are different

DataFrame shape mismatch
[left]:  (2, 15)
[right]: (0, 15)



Ran 1 test in 21.069s

FAILED (failures=1)

Process finished with exit code 1
